<?xml version="1.0" ?>
<!--
  Environment-spike world (doc16 §10). Smallest decisive scene to answer:
  "headless gz sim + LiDAR sensor + ros_gz_bridge on tiryoh/ros2-desktop-vnc:jazzy (ARM64)?"
  NOT the real diorama — throwaway probe. Frozen names used so the bridge/sensor config
  graduates into the real warehouse_sim/warehouse_description:
    model bot1, links base_link / lidar_link, frames bot1/odom + bot1/base_link + bot1/lidar_link,
    topics /bot1/{scan,odom,cmd_vel}.
  Path A: sensors render_engine=ogre2 (GPU/EGL; under software GL via LIBGL_ALWAYS_SOFTWARE=1).
  Path B fallback (run_spike.sh generates min_lidar_cpu.sdf): render_engine=ogre (ogre1).
-->
<sdf version="1.8">
  <world name="spike">
    <physics name="1ms" type="ignored">
      <max_step_size>0.001</max_step_size>
      <real_time_factor>1.0</real_time_factor>
    </physics>

    <plugin filename="gz-sim-physics-system" name="gz::sim::systems::Physics"/>
    <plugin filename="gz-sim-user-commands-system" name="gz::sim::systems::UserCommands"/>
    <plugin filename="gz-sim-scene-broadcaster-system" name="gz::sim::systems::SceneBroadcaster"/>
    <plugin filename="gz-sim-sensors-system" name="gz::sim::systems::Sensors">
      <render_engine>ogre2</render_engine>
    </plugin>

    <light type="directional" name="sun">
      <cast_shadows>false</cast_shadows>
      <pose>0 0 10 0 0 0</pose>
      <diffuse>0.8 0.8 0.8 1</diffuse>
      <specular>0.2 0.2 0.2 1</specular>
      <direction>-0.5 0.1 -0.9</direction>
    </light>

    <model name="ground_plane">
      <static>true</static>
      <link name="link">
        <collision name="collision">
          <geometry><plane><normal>0 0 1</normal><size>20 20</size></plane></geometry>
        </collision>
        <visual name="visual">
          <geometry><plane><normal>0 0 1</normal><size>20 20</size></plane></geometry>
          <material><ambient>0.8 0.8 0.8 1</ambient><diffuse>0.8 0.8 0.8 1</diffuse></material>
        </visual>
      </link>
    </model>

    <!-- obstacle in front so the lidar returns finite (non-inf) ranges -->
    <model name="obstacle">
      <static>true</static>
      <pose>3.0 0 0.5 0 0 0</pose>
      <link name="link">
        <collision name="collision">
          <geometry><box><size>0.5 2.0 1.0</size></box></geometry>
        </collision>
        <visual name="visual">
          <geometry><box><size>0.5 2.0 1.0</size></box></geometry>
          <material><ambient>0.6 0.2 0.2 1</ambient><diffuse>0.6 0.2 0.2 1</diffuse></material>
        </visual>
      </link>
    </model>

    <!-- bot1: canonical gz diff-drive proportions (known-stable physics) renamed to the
         frozen contract names + a 360 deg gpu_lidar. Spike only needs /scan non-empty,
         /odom ticking, and /cmd_vel to move it; exact scale is not the real robot. -->
    <model name="bot1" canonical_link="base_link">
      <pose relative_to="world">0 0 0 0 0 0</pose>

      <link name="base_link">
        <pose relative_to="__model__">0 0 0.4 0 0 0</pose>
        <inertial>
          <mass>1.14395</mass>
          <inertia>
            <ixx>0.126164</ixx><ixy>0</ixy><ixz>0</ixz>
            <iyy>0.416519</iyy><iyz>0</iyz><izz>0.481014</izz>
          </inertia>
        </inertial>
        <collision name="collision">
          <geometry><box><size>1.0 0.6 0.4</size></box></geometry>
        </collision>
        <visual name="visual">
          <geometry><box><size>1.0 0.6 0.4</size></box></geometry>
          <material><ambient>0.2 0.3 0.7 1</ambient><diffuse>0.2 0.3 0.7 1</diffuse></material>
        </visual>
      </link>

      <link name="lidar_link">
        <pose relative_to="base_link">0 0 0.3 0 0 0</pose>
        <inertial>
          <mass>0.05</mass>
          <inertia><ixx>1e-5</ixx><ixy>0</ixy><ixz>0</ixz><iyy>1e-5</iyy><iyz>0</iyz><izz>1e-5</izz></inertia>
        </inertial>
        <visual name="visual">
          <geometry><cylinder><radius>0.08</radius><length>0.08</length></cylinder></geometry>
          <material><ambient>0.1 0.1 0.1 1</ambient><diffuse>0.1 0.1 0.1 1</diffuse></material>
        </visual>
        <sensor name="lidar" type="gpu_lidar">
          <pose>0 0 0 0 0 0</pose>
          <topic>/bot1/scan</topic>
          <gz_frame_id>bot1/lidar_link</gz_frame_id>
          <update_rate>10</update_rate>
          <always_on>1</always_on>
          <visualize>true</visualize>
          <lidar>
            <scan>
              <horizontal>
                <samples>360</samples>
                <resolution>1</resolution>
                <min_angle>-3.14159</min_angle>
                <max_angle>3.14159</max_angle>
              </horizontal>
              <vertical>
                <samples>1</samples>
                <resolution>1</resolution>
                <min_angle>0</min_angle>
                <max_angle>0</max_angle>
              </vertical>
            </scan>
            <range>
              <min>0.08</min>
              <max>12.0</max>
              <resolution>0.01</resolution>
            </range>
          </lidar>
        </sensor>
      </link>

      <link name="left_wheel">
        <pose relative_to="base_link">-0.3 0.36 -0.2 -1.5707 0 0</pose>
        <inertial>
          <mass>1.0</mass>
          <inertia><ixx>0.0435</ixx><ixy>0</ixy><ixz>0</ixz><iyy>0.0435</iyy><iyz>0</iyz><izz>0.08</izz></inertia>
        </inertial>
        <collision name="collision">
          <geometry><sphere><radius>0.2</radius></sphere></geometry>
        </collision>
        <visual name="visual">
          <geometry><sphere><radius>0.2</radius></sphere></geometry>
          <material><ambient>0.1 0.1 0.1 1</ambient><diffuse>0.1 0.1 0.1 1</diffuse></material>
        </visual>
      </link>

      <link name="right_wheel">
        <pose relative_to="base_link">-0.3 -0.36 -0.2 -1.5707 0 0</pose>
        <inertial>
          <mass>1.0</mass>
          <inertia><ixx>0.0435</ixx><ixy>0</ixy><ixz>0</ixz><iyy>0.0435</iyy><iyz>0</iyz><izz>0.08</izz></inertia>
        </inertial>
        <collision name="collision">
          <geometry><sphere><radius>0.2</radius></sphere></geometry>
        </collision>
        <visual name="visual">
          <geometry><sphere><radius>0.2</radius></sphere></geometry>
          <material><ambient>0.1 0.1 0.1 1</ambient><diffuse>0.1 0.1 0.1 1</diffuse></material>
        </visual>
      </link>

      <link name="caster">
        <pose relative_to="base_link">0.4 0 -0.2 0 0 0</pose>
        <inertial>
          <mass>0.5</mass>
          <inertia><ixx>0.008</ixx><ixy>0</ixy><ixz>0</ixz><iyy>0.008</iyy><iyz>0</iyz><izz>0.008</izz></inertia>
        </inertial>
        <collision name="collision">
          <geometry><sphere><radius>0.2</radius></sphere></geometry>
          <surface><friction><ode><mu>0.001</mu><mu2>0.001</mu2></ode></friction></surface>
        </collision>
        <visual name="visual">
          <geometry><sphere><radius>0.2</radius></sphere></geometry>
          <material><ambient>0.3 0.3 0.3 1</ambient><diffuse>0.3 0.3 0.3 1</diffuse></material>
        </visual>
      </link>

      <joint name="lidar_joint" type="fixed">
        <parent>base_link</parent>
        <child>lidar_link</child>
      </joint>

      <joint name="left_wheel_joint" type="revolute">
        <pose relative_to="left_wheel"/>
        <parent>base_link</parent>
        <child>left_wheel</child>
        <axis>
          <xyz expressed_in="__model__">0 1 0</xyz>
          <limit><lower>-1.79769e+308</lower><upper>1.79769e+308</upper></limit>
        </axis>
      </joint>

      <joint name="right_wheel_joint" type="revolute">
        <pose relative_to="right_wheel"/>
        <parent>base_link</parent>
        <child>right_wheel</child>
        <axis>
          <xyz expressed_in="__model__">0 1 0</xyz>
          <limit><lower>-1.79769e+308</lower><upper>1.79769e+308</upper></limit>
        </axis>
      </joint>

      <joint name="caster_joint" type="ball">
        <parent>base_link</parent>
        <child>caster</child>
      </joint>

      <plugin filename="gz-sim-diff-drive-system" name="gz::sim::systems::DiffDrive">
        <left_joint>left_wheel_joint</left_joint>
        <right_joint>right_wheel_joint</right_joint>
        <wheel_separation>1.2</wheel_separation>
        <wheel_radius>0.2</wheel_radius>
        <topic>/bot1/cmd_vel</topic>
        <odom_topic>/bot1/odom</odom_topic>
        <frame_id>bot1/odom</frame_id>
        <child_frame_id>bot1/base_link</child_frame_id>
        <odom_publish_frequency>30</odom_publish_frequency>
      </plugin>
    </model>
  </world>
</sdf>
